nohup: ignoring input
Note: Environment variable`HF_TOKEN` is set and is the current active token independently from the token you've just configured.
/home/lenovo/alkestrup/venv/lib/python3.10/site-packages/huggingface_hub/file_download.py:797: FutureWarning: `resume_download` is deprecated and will be removed in version 1.0.0. Downloads always resume when possible. If you want to force a new download, use `force_download=True`.
  warnings.warn(
Special tokens have been added in the vocabulary, make sure the associated word embeddings are fine-tuned or trained.
Traceback (most recent call last):
  File "/home/lenovo/alkestrup/venv/lib/python3.10/site-packages/huggingface_hub/utils/_http.py", line 406, in hf_raise_for_status
    response.raise_for_status()
  File "/home/lenovo/alkestrup/venv/lib/python3.10/site-packages/requests/models.py", line 1024, in raise_for_status
    raise HTTPError(http_error_msg, response=self)
requests.exceptions.HTTPError: 404 Client Error: Not Found for url: https://huggingface.co/hf_mntp_model/resolve/main/adapter_config.json

The above exception was the direct cause of the following exception:

Traceback (most recent call last):
  File "/home/lenovo/alkestrup/venv/lib/python3.10/site-packages/transformers/utils/hub.py", line 398, in cached_file
    resolved_file = hf_hub_download(
  File "/home/lenovo/alkestrup/venv/lib/python3.10/site-packages/huggingface_hub/utils/_validators.py", line 114, in _inner_fn
    return fn(*args, **kwargs)
  File "/home/lenovo/alkestrup/venv/lib/python3.10/site-packages/huggingface_hub/file_download.py", line 862, in hf_hub_download
    return _hf_hub_download_to_cache_dir(
  File "/home/lenovo/alkestrup/venv/lib/python3.10/site-packages/huggingface_hub/file_download.py", line 969, in _hf_hub_download_to_cache_dir
    _raise_on_head_call_error(head_call_error, force_download, local_files_only)
  File "/home/lenovo/alkestrup/venv/lib/python3.10/site-packages/huggingface_hub/file_download.py", line 1484, in _raise_on_head_call_error
    raise head_call_error
  File "/home/lenovo/alkestrup/venv/lib/python3.10/site-packages/huggingface_hub/file_download.py", line 1376, in _get_metadata_or_catch_error
    metadata = get_hf_file_metadata(
  File "/home/lenovo/alkestrup/venv/lib/python3.10/site-packages/huggingface_hub/utils/_validators.py", line 114, in _inner_fn
    return fn(*args, **kwargs)
  File "/home/lenovo/alkestrup/venv/lib/python3.10/site-packages/huggingface_hub/file_download.py", line 1296, in get_hf_file_metadata
    r = _request_wrapper(
  File "/home/lenovo/alkestrup/venv/lib/python3.10/site-packages/huggingface_hub/file_download.py", line 277, in _request_wrapper
    response = _request_wrapper(
  File "/home/lenovo/alkestrup/venv/lib/python3.10/site-packages/huggingface_hub/file_download.py", line 301, in _request_wrapper
    hf_raise_for_status(response)
  File "/home/lenovo/alkestrup/venv/lib/python3.10/site-packages/huggingface_hub/utils/_http.py", line 454, in hf_raise_for_status
    raise _format(RepositoryNotFoundError, message, response) from e
huggingface_hub.errors.RepositoryNotFoundError: 404 Client Error. (Request ID: Root=1-6740df1c-6262a7262bff84a06dd7313f;80317fec-bccb-4b4a-bd33-4acc97279f97)

Repository Not Found for url: https://huggingface.co/hf_mntp_model/resolve/main/adapter_config.json.
Please make sure you specified the correct `repo_id` and `repo_type`.
If you are trying to access a private or gated repo, make sure you are authenticated.

The above exception was the direct cause of the following exception:

Traceback (most recent call last):
  File "/home/lenovo/alkestrup/dtu-deep-project/seb_eval/seb_l2v_eval.py", line 45, in <module>
    model = AutoModel.from_pretrained(
  File "/home/lenovo/alkestrup/venv/lib/python3.10/site-packages/transformers/models/auto/auto_factory.py", line 502, in from_pretrained
    maybe_adapter_path = find_adapter_config_file(
  File "/home/lenovo/alkestrup/venv/lib/python3.10/site-packages/transformers/utils/peft_utils.py", line 87, in find_adapter_config_file
    adapter_cached_filename = cached_file(
  File "/home/lenovo/alkestrup/venv/lib/python3.10/site-packages/transformers/utils/hub.py", line 421, in cached_file
    raise EnvironmentError(
OSError: hf_mntp_model is not a local folder and is not a valid model identifier listed on 'https://huggingface.co/models'
If this is a private repository, make sure to pass a token having permission to this repo either by logging in with `huggingface-cli login` or by passing `token=<your_token>`
